<?xml version="1.0" encoding="utf-8"?>

<robot name="smartsix">
    
    <link name="base_link">
        <visual>
            <origin xyz="0 0 0" rpy="0 0 0"/>
            <geometry>
                    <mesh filename="package://fanuc_description/fanuc_meshes/visual/link_0.dae" />
            </geometry>
        </visual>

        <collision>
            <origin xyz="0 0 0" rpy="0 0 0"/>
            <geometry>
                <mesh filename="package://fanuc_description/fanuc_meshes/collision/link_0.stl"/>
            </geometry>
        </collision>
    </link>

    <link name="link1">
        <visual>
            <origin xyz="0 0 0" rpy="0 0 0"/>
            <geometry>
                    <mesh filename="package://fanuc_description/fanuc_meshes/visual/link_1.dae" />
            </geometry>
        </visual>

        <collision>
            <origin xyz="0 0 0" rpy="0 0 0"/>
            <geometry>
                <mesh filename="package://fanuc_description/fanuc_meshes/collision/link_1.stl"/>
            </geometry>
        </collision>
    </link>

    <link name="link2">
        <visual>
            <origin xyz="-0.52 -0.15 0" rpy="1.5708 0 1.5708"/>
            <geometry>
                    <mesh filename="package://fanuc_description/fanuc_meshes/visual/link_2.dae" />
            </geometry>
        </visual>

        <collision>
            <origin xyz="-0.52 -0.15 0" rpy="1.5708 0 1.5708"/>
            <geometry>
                <mesh filename="package://fanuc_description/fanuc_meshes/collision/link_2.stl"/>
            </geometry>
        </collision>
    </link>

    <link name="link3">
        <visual>
            <origin xyz="-1.3 -0.15 0" rpy="1.5708 0 1.5708"/>
            <geometry>
                    <mesh filename="package://fanuc_description/fanuc_meshes/visual/link_3.dae" />
            </geometry>
        </visual>

        <collision>
            <origin xyz="-1.3 -0.15 0" rpy="1.5708 0 1.5708"/>
            <geometry>
                <mesh filename="package://fanuc_description/fanuc_meshes/collision/link_3.stl"/>
            </geometry>
        </collision>
    </link>

    <link name="link4">
        <visual>
            <origin xyz="1.475 0 -0.145" rpy="0 -1.5708 0"/>
            <geometry>
                    <mesh filename="package://fanuc_description/fanuc_meshes/visual/link_4.dae" />
            </geometry>
        </visual>

        <collision>
            <origin xyz="1.475 0 -0.145" rpy="0 -1.5708 0"/>
            <geometry>
                <mesh filename="package://fanuc_description/fanuc_meshes/collision/link_4.stl"/>
            </geometry>
        </collision>
    </link>

    <link name="link5">
        <visual>
            <origin xyz="-1.45 -0.95 0" rpy="1.5708 0 1.5708"/>
            <geometry>
                    <mesh filename="package://fanuc_description/fanuc_meshes/visual/link_5.dae" />
            </geometry>
        </visual>

        <collision>
            <origin xyz="-1.45 -0.95 0" rpy="1.5708 0 1.5708"/>
            <geometry>
                <mesh filename="package://fanuc_description/fanuc_meshes/collision/link_5.stl"/>
            </geometry>
        </collision>
    </link>

    <link name="link6">
        <visual>
            <origin xyz="0 0 0" rpy="0 0 0"/>
            <geometry>
                    <mesh filename="package://fanuc_description/fanuc_meshes/visual/link_6.dae" />
            </geometry>
        </visual>

        <collision>
            <origin xyz="0 0 0" rpy="0 0 0"/>
            <geometry>
                <mesh filename="package://fanuc_description/fanuc_meshes/collision/link_6.stl"/>
            </geometry>
        </collision>
    </link>

    <link name="flange">
    </link>


    <joint name="joint1" type="revolute">
        <parent link="base_link"/>
        <child link="link1"/>
        <axis xyz="0 0 1"/>
        <origin xyz="0 0 0" rpy="0 0 0"/>
        <limit lower="-2.96706" upper="2.96706" effort="12" velocity="2.44"/>
    </joint>

    <joint name="joint2" type="revolute">
        <parent link="link1"/>
        <child link="link2"/>
        <axis xyz="0 0 1"/>
        <origin xyz="0.15 0 0.525" rpy="-1.5708 0 0"/>
        <limit lower="-2.27" upper="2.27" effort="12" velocity="2.44"/>
    </joint>

    <joint name="joint3" type="revolute">
        <parent link="link2"/>
        <child link="link3"/>
        <axis xyz="0 0 1"/>
        <origin xyz="0.79 0 0" rpy="0 0 0"/>
        <limit lower="-4" upper="4" effort="12" velocity="2.44"/>
    </joint>

    <joint name="joint4" type="revolute">
        <parent link="link3"/>
        <child link="link4"/>
        <axis xyz="0 0 1"/>
        <origin xyz="0.15 0 0" rpy="-1.5708 0 0"/>
        <limit lower="-3.49" upper="3.49" effort="12" velocity="2.44"/>
    </joint>

    <joint name="joint5" type="revolute">
        <parent link="link4"/>
        <child link="link5"/>
        <axis xyz="0 0 1"/>
        <origin xyz="0 0 0.835" rpy="1.5708 0 0"/>
        <limit lower="-2.44" upper="2.45" effort="12" velocity="2.44"/>
    </joint>

    <joint name="joint6" type="revolute">
        <parent link="link5"/>
        <child link="link6"/>
        <axis xyz="0 0 1"/>
        <origin xyz="0 0 0" rpy="-1.5708 0 0"/>
        <limit lower="-7.85" upper="7.86" effort="12" velocity="2.44"/>
    </joint>

    <joint name="flange" type="fixed">
        <parent link="link6"/>
        <child link="flange"/>
        <axis xyz="0 0 1"/>
        <origin xyz="0 0 0.1" rpy="0 0 0"/>
    </joint>

</robot>
